[2021-12-06 17:57:03,130] - google_bigquery.py - INFO - Credentials are valid
[2021-12-06 17:57:04,113] - google_bigquery.py - INFO - dataset abc was created
[2021-12-06 17:57:04,478] - google_bigquery.py - INFO - table def has just been created
[2021-12-06 17:57:04,478] - google_bigquery.py - ERROR - Filename is not valid , data has not been loaded
[2021-12-06 17:57:38,935] - google_bigquery.py - INFO - Credentials are valid
[2021-12-06 17:57:39,649] - google_bigquery.py - INFO - dataset abc has already been created before
[2021-12-06 17:57:40,141] - google_bigquery.py - INFO - table def was created before
[2021-12-06 18:00:09,644] - google_bigquery.py - INFO - Credentials are valid
[2021-12-06 18:00:10,437] - google_bigquery.py - INFO - dataset abc has already been created before
[2021-12-06 18:00:10,754] - google_bigquery.py - INFO - table def was created before
[2021-12-06 18:00:12,567] - google_bigquery.py - INFO - DATA WAS LOADED FROM symbols.csv TO THE TABLE :def
[2021-12-06 18:11:04,661] - google_bigquery.py - INFO - Credentials are valid
[2021-12-06 18:11:05,211] - google_bigquery.py - INFO - dataset abc has already been created before
[2021-12-06 18:11:05,619] - google_bigquery.py - INFO - table def was created before
[2021-12-06 18:11:05,620] - google_bigquery.py - ERROR - File with credentials does not exist or filename is not valid
[2021-12-07 15:12:07,830] - google_bigquery.py - INFO - Credentials are valid
[2021-12-07 15:12:19,230] - google_bigquery.py - INFO - dataset abc has already been created before
[2021-12-07 15:12:19,623] - google_bigquery.py - INFO - table def was created before
[2021-12-07 15:12:19,623] - google_bigquery.py - ERROR - Incorrect json/csv file given in the function argument
[2021-12-07 15:12:36,745] - google_bigquery.py - ERROR - File with credentials does not exist or filename is not valid
[2021-12-07 15:44:26,245] - google_bigquery.py - INFO - Credentials are valid
[2021-12-07 15:44:27,419] - google_bigquery.py - ERROR - Output file latest234.json is not CSV , data hasnot been loaded
[2021-12-07 15:44:42,792] - google_bigquery.py - INFO - Credentials are valid
[2021-12-07 15:44:43,495] - google_bigquery.py - ERROR - Output file latest234.csv is not CSV , data hasnot been loaded
[2021-12-07 15:45:23,431] - google_bigquery.py - INFO - Credentials are valid
[2021-12-07 16:05:44,441] - postgres.py - INFO - Succesfully connected to Postgres
[2021-12-07 16:05:44,441] - postgres.py - INFO - Succesfully connected to Postgres
[2021-12-07 16:05:44,441] - postgres.py - INFO - Succesfully connected to Postgres
[2021-12-07 16:06:42,815] - postgres.py - INFO - Succesfully connected to Postgres
[2021-12-07 16:06:42,815] - postgres.py - INFO - Succesfully connected to Postgres
[2021-12-07 16:06:42,815] - postgres.py - INFO - Succesfully connected to Postgres
[2021-12-07 16:08:49,908] - postgres.py - INFO - Succesfully connected to Postgres
[2021-12-07 16:08:49,908] - postgres.py - INFO - Succesfully connected to Postgres
[2021-12-07 16:08:49,908] - postgres.py - INFO - Succesfully connected to Postgres
[2021-12-07 16:08:49,909] - postgres.py - WARNING - Table name does not exist
[2021-12-07 16:08:49,909] - postgres.py - WARNING - Table name does not exist
[2021-12-07 16:08:49,909] - postgres.py - WARNING - Table name does not exist
[2021-12-07 16:10:38,508] - postgres.py - INFO - Succesfully connected to Postgres
[2021-12-07 16:10:38,508] - postgres.py - INFO - Succesfully connected to Postgres
[2021-12-07 16:10:38,508] - postgres.py - INFO - Succesfully connected to Postgres
[2021-12-07 16:10:38,509] - postgres.py - WARNING - Table name does not exist
[2021-12-07 16:10:38,509] - postgres.py - WARNING - Table name does not exist
[2021-12-07 16:10:38,509] - postgres.py - WARNING - Table name does not exist
[2021-12-07 16:11:31,038] - postgres.py - INFO - Succesfully connected to Postgres
[2021-12-07 16:11:31,038] - postgres.py - INFO - Succesfully connected to Postgres
[2021-12-07 16:11:31,038] - postgres.py - INFO - Succesfully connected to Postgres
[2021-12-07 16:11:31,038] - postgres.py - WARNING - Table name does not exist
[2021-12-07 16:11:31,038] - postgres.py - WARNING - Table name does not exist
[2021-12-07 16:11:31,038] - postgres.py - WARNING - Table name does not exist
[2021-12-07 16:12:22,055] - postgres.py - INFO - Succesfully connected to Postgres
[2021-12-07 16:12:22,055] - postgres.py - INFO - Succesfully connected to Postgres
[2021-12-07 16:12:22,055] - postgres.py - INFO - Succesfully connected to Postgres
[2021-12-07 16:13:14,447] - postgres.py - INFO - Succesfully connected to Postgres
[2021-12-07 16:13:14,447] - postgres.py - INFO - Succesfully connected to Postgres
[2021-12-07 16:13:14,447] - postgres.py - INFO - Succesfully connected to Postgres
[2021-12-07 16:16:16,517] - postgres.py - INFO - Succesfully connected to Postgres
[2021-12-07 16:16:16,517] - postgres.py - INFO - Succesfully connected to Postgres
[2021-12-07 16:16:16,517] - postgres.py - INFO - Succesfully connected to Postgres
[2021-12-07 16:16:45,683] - postgres.py - INFO - Succesfully connected to Postgres
[2021-12-07 16:16:45,683] - postgres.py - INFO - Succesfully connected to Postgres
[2021-12-07 16:16:45,683] - postgres.py - INFO - Succesfully connected to Postgres
[2021-12-07 16:18:48,120] - postgres.py - INFO - Succesfully connected to Postgres
[2021-12-07 16:18:48,120] - postgres.py - INFO - Succesfully connected to Postgres
[2021-12-07 16:18:48,120] - postgres.py - INFO - Succesfully connected to Postgres
[2021-12-07 16:19:02,433] - postgres.py - INFO - Succesfully connected to Postgres
[2021-12-07 16:19:02,433] - postgres.py - INFO - Succesfully connected to Postgres
[2021-12-07 16:19:02,433] - postgres.py - INFO - Succesfully connected to Postgres
[2021-12-07 16:20:31,475] - postgres.py - INFO - Succesfully connected to Postgres
[2021-12-07 16:20:31,475] - postgres.py - INFO - Succesfully connected to Postgres
[2021-12-07 16:20:31,475] - postgres.py - INFO - Succesfully connected to Postgres
[2021-12-07 16:20:31,476] - postgres.py - INFO -  latest succesfully copied to /home/igor/Рабочий стол/flask-fixer/symbols12312894.csv
[2021-12-07 16:20:31,476] - postgres.py - INFO -  latest succesfully copied to /home/igor/Рабочий стол/flask-fixer/symbols12312894.csv
[2021-12-07 16:20:31,476] - postgres.py - INFO -  latest succesfully copied to /home/igor/Рабочий стол/flask-fixer/symbols12312894.csv
[2021-12-07 16:20:51,075] - postgres.py - INFO - Succesfully connected to Postgres
[2021-12-07 16:20:51,075] - postgres.py - INFO - Succesfully connected to Postgres
[2021-12-07 16:20:51,075] - postgres.py - INFO - Succesfully connected to Postgres
[2021-12-07 16:21:00,788] - postgres.py - INFO - Succesfully connected to Postgres
[2021-12-07 16:21:00,788] - postgres.py - INFO - Succesfully connected to Postgres
[2021-12-07 16:21:00,788] - postgres.py - INFO - Succesfully connected to Postgres
[2021-12-07 16:22:22,316] - postgres.py - INFO - Succesfully connected to Postgres
[2021-12-07 16:22:22,316] - postgres.py - INFO - Succesfully connected to Postgres
[2021-12-07 16:22:22,316] - postgres.py - INFO - Succesfully connected to Postgres
[2021-12-07 16:23:56,630] - postgres.py - INFO - Succesfully connected to Postgres
[2021-12-07 16:23:56,630] - postgres.py - INFO - Succesfully connected to Postgres
[2021-12-07 16:23:56,630] - postgres.py - INFO - Succesfully connected to Postgres
[2021-12-07 16:25:07,210] - postgres.py - INFO - Succesfully connected to Postgres
[2021-12-07 16:25:07,210] - postgres.py - INFO - Succesfully connected to Postgres
[2021-12-07 16:25:07,210] - postgres.py - INFO - Succesfully connected to Postgres
[2021-12-07 16:25:07,210] - postgres.py - WARNING - file path /home/ior/Рабочий стол/flask-fixer/sy4.csv is not correct
[2021-12-07 16:25:07,210] - postgres.py - WARNING - file path /home/ior/Рабочий стол/flask-fixer/sy4.csv is not correct
[2021-12-07 16:25:07,210] - postgres.py - WARNING - file path /home/ior/Рабочий стол/flask-fixer/sy4.csv is not correct
